<?xml version="1.0"?>
<robot name="mannequin">
    <!-- Puts mannequin in Gazebo sim -->
    <gazebo>
        <plugin name="gazebo_ros_control" filename="libgazebo_ros_control.so">
            <robotNamespace>/mannequin</robotNamespace>
        </plugin>
    </gazebo>

    <!-- * * * Link Definitions * * * -->
    <link name="base_link">
        <visual>
            <origin rpy="0.1 0 0" xyz="0 0 0"/>
            <geometry>
                <box size="0.01 0.01 0.01"/>
            </geometry>
        </visual>
	</link>
    <gazebo reference="base_link">
        <kp>1000.0</kp>
        <kd>1000.0</kd>
        <mu1>10.0</mu1>
        <mu2>10.0</mu2>
        <material>Gazebo/White</material>
    </gazebo>


    <link name="body_link">
        <visual>
            <origin rpy="0.0 0 0" xyz="0 0 0"/>
            <geometry>
                <!-- Material color set to white in blender -->
                <mesh filename="package://model_description/models/mannequin/meshes/body_formatted.dae"/>
            </geometry>
        </visual>
        <collision>
            <origin xyz="0 0 0" rpy="0 0 0"/>
            <geometry>
                <cylinder radius="0.2" length="0.1"/>
            </geometry>
        </collision>
        <inertial>
            <origin xyz="0 0 0" rpy="0 0 0"/>
            <mass value="53.6" /> <!-- Assuming 60kg person, with 3.2x2=6.4 kg in arm meat -->
            <!-- interial calc based on box with: width=0.33 length = 0.67 height = 1.7 -->
            <inertia ixx="13.3950866667" ixy="0.0" ixz="0.0" iyy="14.9137533333" iyz="0.0" izz="2.49150666667"/>
        </inertial>
	</link>
    <gazebo reference="body_link">
        <kp>5000.0</kp> <!-- kp, kd need to be this high to avoid falling through the floor -->
        <kd>5000.0</kd>
        <mu1>10.0</mu1>
        <mu2>10.0</mu2>
        <material>Gazebo/White</material>
    </gazebo>
    
    <link name="left_shoulder_roll_link">
        <visual>
            <origin rpy="0 0 0" xyz="0 0 0"/>
            <geometry>
                <sphere radius="0.03"/>
            </geometry>
        </visual>
        <!-- joint included for mobility, does not need collision-->
        <inertial>
            <origin xyz="0 0 0" rpy="0 0 0"/>
            <mass value="0.001" />
            <inertia ixx="3.6e-07" ixy="0.0" ixz="0.0" iyy="3.6e-07" iyz="0.0" izz="3.6e-07"/>
        </inertial>
    </link>
    <gazebo reference="left_shoulder_roll_link">
        <kp>10000.0</kp>
        <kd>10000.0</kd>
        <mu1>10.0</mu1>
        <mu2>10.0</mu2>
        <material>Gazebo/White</material>
    </gazebo>
    
    <link name="left_shoulder_pitch_link">
        <visual>
            <origin rpy="0 0 0" xyz="0 0 0"/>
            <geometry>
                <sphere radius="0.03"/>
            </geometry>
        </visual>
        <!-- joint included for mobility, does not need collision-->
        <inertial>
            <origin xyz="0 0 0" rpy="0 0 0"/>
            <mass value="0.1" />
            <inertia ixx="3.6e-05" ixy="0.0" ixz="0.0" iyy="3.6e-05" iyz="0.0" izz="3.6e-05"/>
        </inertial>
    </link>
    <gazebo reference="left_shoulder_pitch_link">
        <kp>10000.0</kp>
        <kd>10000.0</kd>
        <mu1>10.0</mu1>
        <mu2>10.0</mu2>
        <material>Gazebo/White</material>
    </gazebo>
    
    <link name="left_shoulder_yaw_link">
        <visual>
            <origin rpy="0 0 0" xyz="0 0 0"/>
            <geometry>
                <sphere radius="0.03"/>
            </geometry>
        </visual>
        <!-- joint included for mobility, does not need collision-->
        <inertial>
            <origin xyz="0 0 0" rpy="0 0 0"/>
            <mass value="0.001" />
            <inertia ixx="3.6e-07" ixy="0.0" ixz="0.0" iyy="3.6e-07" iyz="0.0" izz="3.6e-07"/>
        </inertial>
    </link>
    <gazebo reference="left_shoulder_yaw_link">
        <kp>10000.0</kp>
        <kd>10000.0</kd>
        <mu1>10.0</mu1>
        <mu2>10.0</mu2>
        <material>Gazebo/White</material>
    </gazebo>
    


    <link name="upper_left_arm_link">
        <visual>
            <origin rpy="0 0 0" xyz="0 0 0"/>
            <geometry>
                <mesh filename="package://model_description/models/mannequin/meshes/upper_arm_formatted.dae"/>
            </geometry>
        </visual>
        <collision>
            <origin xyz="0 0 0" rpy="0 0 0"/>
            <geometry>
                <cylinder radius="0.03" length="0.3"/>
            </geometry>
        </collision>
        <inertial>
            <origin xyz="0 0 0" rpy="0 0 0"/>
            <mass value="1.6" /> <!-- Assuming 3.2kg arm, and half of it is upper arm-->
            <inertia ixx="0.01236" ixy="0.0" ixz="0.0" iyy="0.01236" iyz="0.0" izz="0.00072"/>
        </inertial>
    </link>
    <gazebo reference="upper_left_arm_link">
        <kp>1000.0</kp>
        <kd>1000.0</kd>
        <mu1>10.0</mu1>
        <mu2>10.0</mu2>
        <material>Gazebo/White</material>
    </gazebo>
    

    <link name="lower_left_arm_link">
        <visual>
            <origin rpy="0 0 0" xyz="0 0 0"/>
            <geometry>
                <mesh filename="package://model_description/models/mannequin/meshes/lower_arm_formatted.dae"/>
            </geometry>
        </visual>
        <collision>
            <origin xyz="0 0 0" rpy="0 0 0"/>
            <geometry>
                <cylinder radius="0.03" length="0.3"/>
            </geometry>
        </collision>
        <inertial>
            <origin xyz="0 0 0" rpy="0 0 0"/>
            <mass value="1.6" /> <!-- Assuming 3.2kg arm, and half of it is lower arm-->
            <inertia ixx="0.01236" ixy="0.0" ixz="0.0" iyy="0.01236" iyz="0.0" izz="0.00072"/>
        </inertial>
    </link>
    <gazebo reference="lower_left_arm_link">
        <kp>1000.0</kp>
        <kd>1000.0</kd>
        <mu1>10.0</mu1>
        <mu2>10.0</mu2>
        <material>Gazebo/White</material>
    </gazebo>
    
    
    <link name="left_hand_link">
        <visual>
            <origin rpy="0 0 0" xyz="0 0 0"/>
            <geometry>
                <mesh filename="package://model_description/models/mannequin/meshes/hand_formatted.dae"/>
            </geometry>
        </visual>
        <collision>
            <origin xyz="0 0 0" rpy="0 0 0"/>
            <geometry>
                <box size="0.03 0.01 0.05"/>
            </geometry>
        </collision>
        <inertial>
            <origin xyz="0 0 0" rpy="0 0 0"/>
            <mass value="0.3" /> <!-- Assuming 60kg person, hands are 0.5% of weight, hand is 0.3kg -->
            <!-- body segment percentages from https://exrx.net/Kinesiology/Segments-->
            <inertia ixx="6.5e-05" ixy="0.0" ixz="0.0" iyy="8.5e-05" iyz="0.0" izz="2.5e-05"/>
        </inertial>
    </link>
    <gazebo reference="left_hand_link">
        <kp>1000.0</kp>
        <kd>1000.0</kd>
        <mu1>10.0</mu1>
        <mu2>10.0</mu2>
        <material>Gazebo/White</material>
    </gazebo>



    <!-- **** Joint Definitions **** -->
    <joint name="base_joint" type="fixed">
        <parent link="base_link"/>
        <child link="body_link"/>
    </joint>
    
    <!-- Left Arm -->
    <joint name="left_shoulder_roll_joint" type="continuous"> <!-- lift shoulder forward -->
        <parent link="body_link"/>
        <child link="left_shoulder_roll_link"/>
        <axis xyz="1 0 0"/>
        <origin xyz="0.14 0.04 1.32" rpy="0 0 0"/>
    </joint>
    <joint name="left_shoulder_pitch_joint" type="revolute"> <!-- lift shoulder up and to the right, (-) commands -->
        <parent link="left_shoulder_roll_link"/>
        <child link="left_shoulder_pitch_link"/>
        <axis xyz="0 1 0"/>
        <origin xyz="0 0 0" rpy="0 0 0"/>
        <limit lower="-1.57" upper="0" effort="4" velocity="0.5"/>
    </joint>
    <joint name="left_shoulder_yaw_joint" type="revolute">
        <parent link="left_shoulder_pitch_link"/>
        <child link="left_shoulder_yaw_link"/>
        <axis xyz="0 0 1"/>
        <origin xyz="0 0 0" rpy="0 0 0"/>
        <limit lower="-1.1" upper="1.5" effort="1" velocity="0.5"/>
    </joint>
    
    
    <joint name="left_shoulder_joint" type="fixed">
        <parent link="left_shoulder_yaw_link"/>
        <child link="upper_left_arm_link"/>
    </joint>
    <joint name="left_elbow_joint" type="revolute">
        <parent link="upper_left_arm_link"/>
        <child link="lower_left_arm_link"/>
        <axis xyz="1 0 0"/>
        <limit lower="0.01" upper="3.0" effort="1" velocity="0.5"/>
        <origin xyz="-0.01 0.012 -0.322" rpy="0 0 0"/>
    </joint>
    <joint name="left_wrist_joint" type="fixed">
        <parent link="lower_left_arm_link"/>
        <child link="left_hand_link"/>=
        <origin xyz="0.0 0.015 -0.23" rpy="0 0 3.14"/>
    </joint>
    
    
    <!-- **** Controller Definitions **** -->
    
    <!-- Left arm -->
    <transmission name="leftshoulderrolltran">
        <type>transmission_interface/SimpleTransmission</type>
        <joint name="left_shoulder_roll_joint">
            <hardwareInterface>hardware_interface/EffortJointInterface</hardwareInterface>
        </joint>
        <actuator name="leftshoulderrollmotor">
            <hardwareInterface>hardware_interface/EffortJointInterface</hardwareInterface>
            <mechanicalReduction>1</mechanicalReduction>
        </actuator>
    </transmission>
    <transmission name="leftshoulderpitchtran">
        <type>transmission_interface/SimpleTransmission</type>
        <joint name="left_shoulder_pitch_joint">
            <hardwareInterface>hardware_interface/EffortJointInterface</hardwareInterface>
        </joint>
        <actuator name="leftshoulderpitchmotor">
            <hardwareInterface>hardware_interface/EffortJointInterface</hardwareInterface>
            <mechanicalReduction>1</mechanicalReduction>
        </actuator>
    </transmission>
    <transmission name="leftshoulderyawtran">
        <type>transmission_interface/SimpleTransmission</type>
        <joint name="left_shoulder_yaw_joint">
            <hardwareInterface>hardware_interface/EffortJointInterface</hardwareInterface>
        </joint>
        <actuator name="leftshoulderyawmotor">
            <hardwareInterface>hardware_interface/EffortJointInterface</hardwareInterface>
            <mechanicalReduction>1</mechanicalReduction>
        </actuator>
    </transmission>
    
    <transmission name="leftelbowtran">
        <type>transmission_interface/SimpleTransmission</type>
        <joint name="left_elbow_joint">
            <hardwareInterface>hardware_interface/EffortJointInterface</hardwareInterface>
        </joint>
        <actuator name="leftelbowmotor">
            <hardwareInterface>hardware_interface/EffortJointInterface</hardwareInterface>
            <mechanicalReduction>1</mechanicalReduction>
        </actuator>
    </transmission>
    
    
    
    
    <link name="right_shoulder_roll_link">
        <visual>
            <origin rpy="0 0 0" xyz="0 0 0"/>
            <geometry>
                <sphere radius="0.03"/>
            </geometry>
        </visual>
        <!-- joint included for mobility, does not need collision-->
        <inertial>
            <origin xyz="0 0 0" rpy="0 0 0"/>
            <mass value="0.001" />
            <inertia ixx="3.6e-07" ixy="0.0" ixz="0.0" iyy="3.6e-07" iyz="0.0" izz="3.6e-07"/>
        </inertial>
    </link>
    <gazebo reference="right_shoulder_roll_link">
        <kp>10000.0</kp>
        <kd>10000.0</kd>
        <mu1>10.0</mu1>
        <mu2>10.0</mu2>
        <material>Gazebo/White</material>
    </gazebo>
    
    <link name="right_shoulder_pitch_link">
        <visual>
            <origin rpy="0 0 0" xyz="0 0 0"/>
            <geometry>
                <sphere radius="0.03"/>
            </geometry>
        </visual>
        <!-- joint included for mobility, does not need collision-->
        <inertial>
            <origin xyz="0 0 0" rpy="0 0 0"/>
            <mass value="0.001" />
            <inertia ixx="3.6e-07" ixy="0.0" ixz="0.0" iyy="3.6e-07" iyz="0.0" izz="3.6e-07"/>
        </inertial>
    </link>
    <gazebo reference="right_shoulder_pitch_link">
        <kp>10000.0</kp>
        <kd>10000.0</kd>
        <mu1>10.0</mu1>
        <mu2>10.0</mu2>
        <material>Gazebo/White</material>
    </gazebo>
    
    <link name="right_shoulder_yaw_link">
        <visual>
            <origin rpy="0 0 0" xyz="0 0 0"/>
            <geometry>
                <sphere radius="0.03"/>
            </geometry>
        </visual>
        <!-- joint included for mobility, does not need collision-->
        <inertial>
            <origin xyz="0 0 0" rpy="0 0 0"/>
            <mass value="0.001" />
            <inertia ixx="3.6e-07" ixy="0.0" ixz="0.0" iyy="3.6e-07" iyz="0.0" izz="3.6e-07"/>
        </inertial>
    </link>
    <gazebo reference="right_shoulder_yaw_link">
        <kp>10000.0</kp>
        <kd>10000.0</kd>
        <mu1>10.0</mu1>
        <mu2>10.0</mu2>
        <material>Gazebo/White</material>
    </gazebo>
    


    <link name="upper_right_arm_link">
        <visual>
            <origin rpy="0 0 0" xyz="0 0 0"/>
            <geometry>
                <mesh filename="package://model_description/models/mannequin/meshes/upper_arm_formatted.dae"/>
            </geometry>
        </visual>
        <collision>
            <origin xyz="0 0 0" rpy="0 0 0"/>
            <geometry>
                <cylinder radius="0.03" length="0.3"/>
            </geometry>
        </collision>
        <inertial>
            <origin xyz="0 0 0" rpy="0 0 0"/>
            <mass value="1.6" /> <!-- Assuming 3.2kg arm, and half of it is upper arm-->
            <inertia ixx="0.01236" ixy="0.0" ixz="0.0" iyy="0.01236" iyz="0.0" izz="0.00072"/>
        </inertial>
    </link>
    <gazebo reference="upper_right_arm_link">
        <kp>1000.0</kp>
        <kd>1000.0</kd>
        <mu1>10.0</mu1>
        <mu2>10.0</mu2>
        <material>Gazebo/White</material>
    </gazebo>
    

    <link name="lower_right_arm_link">
        <visual>
            <origin rpy="0 0 0" xyz="0 0 0"/>
            <geometry>
                <mesh filename="package://model_description/models/mannequin/meshes/lower_arm_formatted.dae"/>
            </geometry>
        </visual>
        <collision>
            <origin xyz="0 0 0" rpy="0 0 0"/>
            <geometry>
                <cylinder radius="0.03" length="0.3"/>
            </geometry>
        </collision>
        <inertial>
            <origin xyz="0 0 0" rpy="0 0 0"/>
            <mass value="1.6" /> <!-- Assuming 3.2kg arm, and half of it is lower arm-->
            <inertia ixx="0.01236" ixy="0.0" ixz="0.0" iyy="0.01236" iyz="0.0" izz="0.00072"/>
        </inertial>
    </link>
    <gazebo reference="lower_right_arm_link">
        <kp>1000.0</kp>
        <kd>1000.0</kd>
        <mu1>10.0</mu1>
        <mu2>10.0</mu2>
        <material>Gazebo/White</material>
    </gazebo>
    
    
    <link name="right_hand_link">
        <visual>
            <origin rpy="0 0 0" xyz="0 0 0"/>
            <geometry>
                <mesh filename="package://model_description/models/mannequin/meshes/hand_formatted.dae"/>
            </geometry>
        </visual>
        <collision>
            <origin xyz="0 0 0" rpy="0 0 0"/>
            <geometry>
                <box size="0.03 0.01 0.05"/>
            </geometry>
        </collision>
        <inertial>
            <origin xyz="0 0 0" rpy="0 0 0"/>
            <mass value="0.3" /> <!-- Assuming 60kg person, hands are 0.5% of weight, hand is 0.3kg -->
            <!-- body segment percentages from https://exrx.net/Kinesiology/Segments-->
            <inertia ixx="6.5e-05" ixy="0.0" ixz="0.0" iyy="8.5e-05" iyz="0.0" izz="2.5e-05"/>
        </inertial>
    </link>
    <gazebo reference="right_hand_link">
        <kp>1000.0</kp>
        <kd>1000.0</kd>
        <mu1>10.0</mu1>
        <mu2>10.0</mu2>
        <material>Gazebo/White</material>
    </gazebo>



    <!-- **** Joint Definitions **** -->
    
    <!-- Right Arm -->
    <joint name="right_shoulder_roll_joint" type="continuous"> <!-- lift shoulder forward -->
        <parent link="body_link"/>
        <child link="right_shoulder_roll_link"/>
        <axis xyz="1 0 0"/>
        <origin xyz="-0.15 0.04 1.32" rpy="0 0 0"/>
    </joint>
    <joint name="right_shoulder_pitch_joint" type="revolute"> <!-- lift shoulder up and to the right, (+) commands -->
        <parent link="right_shoulder_roll_link"/>
        <child link="right_shoulder_pitch_link"/>
        <axis xyz="0 1 0"/>
        <origin xyz="0 0 0" rpy="0 0 0"/>
        <limit lower="0" upper="1.57" effort="4" velocity="0.5"/>
    </joint>
    <joint name="right_shoulder_yaw_joint" type="revolute">
        <parent link="right_shoulder_pitch_link"/>
        <child link="right_shoulder_yaw_link"/>
        <axis xyz="0 0 1"/>
        <origin xyz="0 0 0" rpy="0 0 0"/>
        <limit lower="-1.5" upper="1.1" effort="1" velocity="0.5"/>
    </joint>
    
    
    <joint name="right_shoulder_joint" type="fixed">
        <parent link="right_shoulder_yaw_link"/>
        <child link="upper_right_arm_link"/>
    </joint>
    <joint name="right_elbow_joint" type="revolute">
        <parent link="upper_right_arm_link"/>
        <child link="lower_right_arm_link"/>
        <axis xyz="1 0 0"/>
        <limit lower="0.01" upper="3.0" effort="1" velocity="0.5"/>
        <origin xyz="-0.01 0.012 -0.322" rpy="0 0 0"/>
    </joint>
    <joint name="right_wrist_joint" type="fixed">
        <parent link="lower_right_arm_link"/>
        <child link="right_hand_link"/>=
        <origin xyz="0.0 -0.015 -0.23" rpy="0 0 0"/>
    </joint>
    
    
    <!-- **** Controller Definitions **** -->
    
    <!-- Right arm -->
    <transmission name="rightshoulderrolltran">
        <type>transmission_interface/SimpleTransmission</type>
        <joint name="right_shoulder_roll_joint">
            <hardwareInterface>hardware_interface/EffortJointInterface</hardwareInterface>
        </joint>
        <actuator name="rightshoulderrollmotor">
            <hardwareInterface>hardware_interface/EffortJointInterface</hardwareInterface>
            <mechanicalReduction>1</mechanicalReduction>
        </actuator>
    </transmission>
    <transmission name="rightshoulderpitchtran">
        <type>transmission_interface/SimpleTransmission</type>
        <joint name="right_shoulder_pitch_joint">
            <hardwareInterface>hardware_interface/EffortJointInterface</hardwareInterface>
        </joint>
        <actuator name="rightshoulderpitchmotor">
            <hardwareInterface>hardware_interface/EffortJointInterface</hardwareInterface>
            <mechanicalReduction>1</mechanicalReduction>
        </actuator>
    </transmission>
    <transmission name="rightshoulderyawtran">
        <type>transmission_interface/SimpleTransmission</type>
        <joint name="right_shoulder_yaw_joint">
            <hardwareInterface>hardware_interface/EffortJointInterface</hardwareInterface>
        </joint>
        <actuator name="rightshoulderyawmotor">
            <hardwareInterface>hardware_interface/EffortJointInterface</hardwareInterface>
            <mechanicalReduction>1</mechanicalReduction>
        </actuator>
    </transmission>
    
    <transmission name="rightelbowtran">
        <type>transmission_interface/SimpleTransmission</type>
        <joint name="right_elbow_joint">
            <hardwareInterface>hardware_interface/EffortJointInterface</hardwareInterface>
        </joint>
        <actuator name="rightelbowmotor">
            <hardwareInterface>hardware_interface/EffortJointInterface</hardwareInterface>
            <mechanicalReduction>1</mechanicalReduction>
        </actuator>
    </transmission>

</robot>
