<?xml version="1.0" ?>
<!-- =================================================================================== -->
<!-- |    This document was autogenerated by xacro from mannequin_fully_articulated.urdf.xacro | -->
<!-- |    EDITING THIS FILE BY HAND IS NOT RECOMMENDED                                 | -->
<!-- =================================================================================== -->
<robot name="mannequin">
  <!-- Body and weight measurements come from "Kodak's Ergonomic Design for People at Work" 50th percentile woman -->
  <!-- Puts mannequin in Gazebo sim -->
  <gazebo>
    <plugin filename="libgazebo_ros_control.so" name="gazebo_ros_control">
      <robotNamespace>/mannequin</robotNamespace>
    </plugin>
  </gazebo>
  <!-- * * * Link Definitions * * * -->
  <link name="base_link">
    <!-- Base link allows the body to "float"-->
    <visual>
      <origin rpy="0 0 0" xyz="0 0 0"/>
      <geometry>
        <cylinder length="0.03" radius="0.6"/>
      </geometry>
    </visual>
    <collision>
      <origin rpy="0 0 0" xyz="0 0 0"/>
      <geometry>
        <cylinder length="0.03" radius="0.6"/>
      </geometry>
    </collision>
  </link>
  <gazebo reference="base_link">
    <kp>50000.0</kp>
    <kd>50000.0</kd>
    <mu1>10.0</mu1>
    <mu2>10.0</mu2>
    <material>Gazebo/White</material>
  </gazebo>
  <link name="lower_body_link">
    <visual>
      <origin rpy="0.0 0 0" xyz="0 0 0"/>
      <geometry>
        <!-- Material color set to white in blender -->
        <mesh filename="package://mannequin/models/mannequin/meshes/lower_body_formatted.dae"/>
      </geometry>
    </visual>
    <collision>
      <origin rpy="0 0 0" xyz="0 0 0"/>
      <geometry>
        <mesh filename="package://mannequin/models/mannequin/meshes/lower_body_low_poly.dae"/>
      </geometry>
    </collision>
    <inertial>
      <origin rpy="-0.01 0 0" xyz="0 0 0.145"/>
      <mass value="15.3"/>
      <inertia ixx="0.2913375" ixy="0.0" ixz="0.0" iyy="0.162920775" iyz="0.0" izz="0.239803275"/>
    </inertial>
  </link>
  <gazebo reference="lower_body_link">
    <kp>5000.0</kp>
    <kd>5000.0</kd>
    <mu1>10.0</mu1>
    <mu2>10.0</mu2>
    <material>Gazebo/White</material>
  </gazebo>
  <link name="upper_body_link">
    <visual>
      <origin rpy="0.01 0 0" xyz="0 -0.005 0"/>
      <geometry>
        <!-- Material color set to white in blender -->
        <mesh filename="package://mannequin/models/mannequin/meshes/upper_body_formatted.dae"/>
      </geometry>
    </visual>
    <collision>
      <origin rpy="0 0 0" xyz="0 0 0"/>
      <geometry>
        <mesh filename="package://mannequin/models/mannequin/meshes/upper_body_low_poly.dae"/>
      </geometry>
    </collision>
    <inertial>
      <origin rpy="0 0 0" xyz="0 0 0.145"/>
      <mass value="15.3"/>
      <inertia ixx="0.2913375" ixy="0.0" ixz="0.0" iyy="0.162920775" iyz="0.0" izz="0.239803275"/>
    </inertial>
  </link>
  <gazebo reference="upper_body_link">
    <kp>10000.0</kp>
    <kd>10000.0</kd>
    <mu1>10.0</mu1>
    <mu2>10.0</mu2>
    <material>Gazebo/White</material>
  </gazebo>
  <link name="head_link">
    <visual>
      <origin rpy="0.0 0 0" xyz="0 0 0"/>
      <geometry>
        <!-- Material color set to white in blender -->
        <mesh filename="package://mannequin/models/mannequin/meshes/head_formatted.dae"/>
      </geometry>
    </visual>
    <collision>
      <origin rpy="0 0 0" xyz="0 0 0.073"/>
      <geometry>
        <sphere radius="0.073"/>
      </geometry>
    </collision>
    <inertial>
      <origin rpy="0 0 0" xyz="0 0 0.073"/>
      <mass value="4.7"/>
      <inertia ixx="0.01001852" ixy="0.0" ixz="0.0" iyy="0.01001852" iyz="0.0" izz="0.01001852"/>
    </inertial>
  </link>
  <gazebo reference="head_link">
    <kp>10000.0</kp>
    <kd>10000.0</kd>
    <mu1>10.0</mu1>
    <mu2>10.0</mu2>
    <material>Gazebo/White</material>
  </gazebo>
  <!-- Torso Joint definitions -->
  <joint name="base_joint" type="fixed">
    <parent link="base_link"/>
    <child link="lower_body_link"/>
    <origin rpy="0 0 0" xyz="0 0 1"/>
  </joint>
  <joint name="torso_mid_joint" type="revolute">
    <hardwareInterface>hardware_interface/EffortJointInterface</hardwareInterface>
    <parent link="lower_body_link"/>
    <child link="upper_body_link"/>
    <axis xyz="1 0 0"/>
    <!-- As is, the mannequin torso can only bend side to side, as this is what I have ROM data on-->
    <limit effort="1000" lower="-0.611" upper="0.611" velocity="0.5"/>
    <origin rpy="0 0 0" xyz="0 0 0.265"/>
  </joint>
  <joint name="neck_joint" type="revolute">
    <hardwareInterface>hardware_interface/EffortJointInterface</hardwareInterface>
    <parent link="upper_body_link"/>
    <child link="head_link"/>
    <axis xyz="1 0 0"/>
    <!-- As is, the mannequin head can only tilt left/right to simplify the joint-->
    <limit effort="200" lower="-0.785" upper="0.785" velocity="0.5"/>
    <origin rpy="0 0 0" xyz="0 0.0 0.358"/>
  </joint>
  <transmission name="torsotran">
    <type>transmission_interface/SimpleTransmission</type>
    <joint name="torso_mid_joint">
      <hardwareInterface>hardware_interface/EffortJointInterface</hardwareInterface>
    </joint>
    <actuator name="torsomotor">
      <mechanicalReduction>50</mechanicalReduction>
    </actuator>
  </transmission>
  <transmission name="necktran">
    <type>transmission_interface/SimpleTransmission</type>
    <joint name="neck_joint">
      <hardwareInterface>hardware_interface/EffortJointInterface</hardwareInterface>
    </joint>
    <actuator name="headmotor">
      <mechanicalReduction>50</mechanicalReduction>
    </actuator>
  </transmission>
  <!-- Shoulder and upper arm definitions-->
  <!-- "invisible" links that add DOF to the shoulder -->
  <link name="left_shoulder_roll_link">
    <visual>
      <origin rpy="0 0 0" xyz="0 0 0"/>
      <geometry>
        <sphere radius="0.01"/>
      </geometry>
    </visual>
    <inertial>
      <origin rpy="0 0 0" xyz="0 0 0"/>
      <mass value="0.01"/>
      <inertia ixx="4e-07" ixy="0.0" ixz="0.0" iyy="4e-07" iyz="0.0" izz="4e-07"/>
    </inertial>
  </link>
  <gazebo reference="left_shoulder_roll_link">
    <kp>10000.0</kp>
    <kd>10000.0</kd>
    <mu1>10.0</mu1>
    <mu2>10.0</mu2>
    <material>Gazebo/Red</material>
  </gazebo>
  <link name="left_shoulder_pitch_link">
    <visual>
      <origin rpy="0 0 0" xyz="0 0 0"/>
      <geometry>
        <sphere radius="0.01"/>
      </geometry>
    </visual>
    <inertial>
      <origin rpy="0 0 0" xyz="0 0 0"/>
      <mass value="0.01"/>
      <inertia ixx="4e-07" ixy="0.0" ixz="0.0" iyy="4e-07" iyz="0.0" izz="4e-07"/>
    </inertial>
  </link>
  <gazebo reference="left_shoulder_pitch_link">
    <kp>10000.0</kp>
    <kd>10000.0</kd>
    <mu1>10.0</mu1>
    <mu2>10.0</mu2>
    <material>Gazebo/Green</material>
  </gazebo>
  <link name="left_shoulder_yaw_link">
    <visual>
      <origin rpy="0 0 0" xyz="0 0 0"/>
      <geometry>
        <sphere radius="0.01"/>
      </geometry>
    </visual>
    <inertial>
      <origin rpy="0 0 0" xyz="0 0 0"/>
      <mass value="0.01"/>
      <inertia ixx="4e-07" ixy="0.0" ixz="0.0" iyy="4e-07" iyz="0.0" izz="4e-07"/>
    </inertial>
  </link>
  <gazebo reference="left_shoulder_yaw_link">
    <kp>10000.0</kp>
    <kd>10000.0</kd>
    <mu1>10.0</mu1>
    <mu2>10.0</mu2>
    <material>Gazebo/Blue</material>
  </gazebo>
  <link name="left_upper_arm_link">
    <visual>
      <origin rpy="0.0 0 0" xyz="0 0 0"/>
      <geometry>
        <!-- Material color set to white in blender -->
        <mesh filename="package://mannequin/models/mannequin/meshes/upper_arm_formatted.dae"/>
      </geometry>
    </visual>
    <collision>
      <origin rpy="0 0 0" xyz="0 0 -0.170"/>
      <geometry>
        <cylinder length="0.341" radius="0.042"/>
      </geometry>
    </collision>
    <inertial>
      <origin rpy="0 0 0" xyz="0 0 -0.170"/>
      <mass value="2.1"/>
      <inertia ixx="0.021275275" ixy="0.0" ixz="0.0" iyy="0.021275275" iyz="0.0" izz="0.0018522"/>
    </inertial>
  </link>
  <gazebo reference="left_upper_arm_link">
    <kp>5000.0</kp>
    <kd>5000.0</kd>
    <mu1>10.0</mu1>
    <mu2>10.0</mu2>
    <material>Gazebo/White</material>
  </gazebo>
  <joint name="left_shoulder_roll_joint" type="revolute">
    <hardwareInterface>hardware_interface/EffortJointInterface</hardwareInterface>
    <parent link="upper_body_link"/>
    <child link="left_shoulder_roll_link"/>
    <axis xyz="1 0 0"/>
    <limit effort="200" lower="-1.05" upper="3.14" velocity="0.5"/>
    <origin rpy="0 0 0" xyz="0 0.188 0.24"/>
  </joint>
  <joint name="left_shoulder_pitch_joint" type="revolute">
    <hardwareInterface>hardware_interface/EffortJointInterface</hardwareInterface>
    <parent link="left_shoulder_roll_link"/>
    <child link="left_shoulder_pitch_link"/>
    <axis xyz="0 1 0"/>
    <limit effort="200" lower="-1.3" upper="3.14" velocity="0.5"/>
    <origin rpy="0 0 0" xyz="0 0 0"/>
  </joint>
  <joint name="left_shoulder_yaw_joint" type="revolute">
    <hardwareInterface>hardware_interface/EffortJointInterface</hardwareInterface>
    <parent link="left_shoulder_pitch_link"/>
    <child link="left_shoulder_yaw_link"/>
    <axis xyz="0 0 -1"/>
    <limit effort="200" lower="-1.0" upper="1.5" velocity="0.5"/>
    <origin rpy="0 0 0" xyz="0 0 0"/>
  </joint>
  <joint name="left_upper_arm_joint" type="fixed">
    <parent link="left_shoulder_yaw_link"/>
    <child link="left_upper_arm_link"/>
    <origin rpy="0 0 0" xyz="0 0 0"/>
  </joint>
  <!-- "Invisible" links for DOF of the elbow (flexion/extension[-0.17,2.62] and supination/pronation[-1.40,1.40]) -->
  <link name="left_elbow_flexion_link">
    <visual>
      <origin rpy="0 0 0" xyz="0 0 0"/>
      <geometry>
        <sphere radius="0.01"/>
      </geometry>
    </visual>
    <inertial>
      <origin rpy="0 0 0" xyz="0 0 0"/>
      <mass value="0.01"/>
      <inertia ixx="4e-07" ixy="0.0" ixz="0.0" iyy="4e-07" iyz="0.0" izz="4e-07"/>
    </inertial>
  </link>
  <gazebo reference="left_elbow_flexion_link">
    <kp>1000.0</kp>
    <kd>1000.0</kd>
    <mu1>10.0</mu1>
    <mu2>10.0</mu2>
    <material>Gazebo/Red</material>
  </gazebo>
  <link name="left_lower_arm_link">
    <visual>
      <origin rpy="0.0 0 0" xyz="0 0 0"/>
      <geometry>
        <!-- Material color set to white in blender -->
        <mesh filename="package://mannequin/models/mannequin/meshes/lower_arm_formatted.dae"/>
      </geometry>
    </visual>
    <collision>
      <origin rpy="0 0 0" xyz="0 0 -0.128"/>
      <geometry>
        <cylinder length="0.25" radius="0.035"/>
      </geometry>
    </collision>
    <inertial>
      <origin rpy="0 0 0" xyz="0 0 -0.128"/>
      <mass value="2.1"/>
      <inertia ixx="0.01038165" ixy="0.0" ixz="0.0" iyy="0.01038165" iyz="0.0" izz="0.0011025"/>
    </inertial>
  </link>
  <gazebo reference="left_lower_arm_link">
    <kp>5000.0</kp>
    <kd>5000.0</kd>
    <mu1>10.0</mu1>
    <mu2>10.0</mu2>
    <material>Gazebo/White</material>
  </gazebo>
  <joint name="left_elbow_flexion_joint" type="revolute">
    <hardwareInterface>hardware_interface/EffortJointInterface</hardwareInterface>
    <parent link="left_upper_arm_link"/>
    <child link="left_elbow_flexion_link"/>
    <axis xyz="0 -1 0"/>
    <limit effort="50" lower="-1.05" upper="3.14" velocity="0.5"/>
    <origin rpy="0 0.05 0" xyz="0 -0.01 -0.34"/>
  </joint>
  <joint name="left_lower_arm_joint" type="fixed">
    <parent link="left_elbow_flexion_link"/>
    <child link="left_lower_arm_link"/>
  </joint>
  <!-- Hand definitions -->
  <!-- Invisible links for flexion/extension and ulnar/radial deviation -->
  <link name="left_wrist_flexion_link">
    <visual>
      <origin rpy="0 0 0" xyz="0 0 0"/>
      <geometry>
        <sphere radius="0.01"/>
      </geometry>
    </visual>
    <inertial>
      <origin rpy="0 0 0" xyz="0 0 0"/>
      <mass value="0.01"/>
      <inertia ixx="4e-07" ixy="0.0" ixz="0.0" iyy="4e-07" iyz="0.0" izz="4e-07"/>
    </inertial>
  </link>
  <gazebo reference="left_wrist_flexion_link">
    <kp>1000.0</kp>
    <kd>1000.0</kd>
    <mu1>10.0</mu1>
    <mu2>10.0</mu2>
    <material>Gazebo/Red</material>
  </gazebo>
  <link name="left_hand_link">
    <visual>
      <origin rpy="0.0 -0.2 3.14" xyz="0 0 0"/>
      <geometry>
        <!-- Material color set to white in blender -->
        <mesh filename="package://mannequin/models/mannequin/meshes/hand_formatted.dae"/>
      </geometry>
    </visual>
    <collision>
      <origin rpy="0 0 0" xyz="0 0 -0.092"/>
      <geometry>
        <box size="0.077 0.028 0.184"/>
      </geometry>
    </collision>
    <inertial>
      <origin rpy="0 0 0" xyz="0 0 -0.092"/>
      <mass value="0.5"/>
      <inertia ixx="0.00144333333333" ixy="0.0" ixz="0.0" iyy="0.00165770833333" iyz="0.0" izz="0.000279708333333"/>
    </inertial>
  </link>
  <gazebo reference="left_hand_link">
    <kp>5000.0</kp>
    <kd>5000.0</kd>
    <mu1>10.0</mu1>
    <mu2>10.0</mu2>
    <material>Gazebo/White</material>
  </gazebo>
  <joint name="left_wrist_flexion_joint" type="revolute">
    <hardwareInterface>hardware_interface/EffortJointInterface</hardwareInterface>
    <parent link="left_lower_arm_link"/>
    <child link="left_wrist_flexion_link"/>
    <axis xyz="1 0 0"/>
    <limit effort="5" lower="-1.396" upper="1.22" velocity="0.5"/>
    <origin rpy="0 0 0" xyz="0 0 -0.25"/>
  </joint>
  <joint name="left_hand_joint" type="fixed">
    <parent link="left_wrist_flexion_link"/>
    <child link="left_hand_link"/>
    <origin rpy="0 0 1.57" xyz="0 0 0"/>
  </joint>
  <!-- ***** Actuator Definitions for arm ***** -->
  <!-- Shoulder actuators -->
  <transmission name="leftshoulderrolltran">
    <type>transmission_interface/SimpleTransmission</type>
    <joint name="left_shoulder_roll_joint">
      <hardwareInterface>hardware_interface/EffortJointInterface</hardwareInterface>
    </joint>
    <actuator name="leftshoulderrollmotor">
      <mechanicalReduction>50</mechanicalReduction>
    </actuator>
  </transmission>
  <transmission name="leftshoulderpitchtran">
    <type>transmission_interface/SimpleTransmission</type>
    <joint name="left_shoulder_pitch_joint">
      <hardwareInterface>hardware_interface/EffortJointInterface</hardwareInterface>
    </joint>
    <actuator name="leftshoulderpitchmotor">
      <mechanicalReduction>50</mechanicalReduction>
    </actuator>
  </transmission>
  <transmission name="leftshoulderyawtran">
    <type>transmission_interface/SimpleTransmission</type>
    <joint name="left_shoulder_yaw_joint">
      <hardwareInterface>hardware_interface/EffortJointInterface</hardwareInterface>
    </joint>
    <actuator name="leftshoulderyawmotor">
      <mechanicalReduction>50</mechanicalReduction>
    </actuator>
  </transmission>
  <!-- Elbow actuators -->
  <transmission name="leftelbowflexiontran">
    <type>transmission_interface/SimpleTransmission</type>
    <joint name="left_elbow_flexion_joint">
      <hardwareInterface>hardware_interface/EffortJointInterface</hardwareInterface>
    </joint>
    <actuator name="leftelbowflexionmotor">
      <mechanicalReduction>50</mechanicalReduction>
    </actuator>
  </transmission>
  <!-- Wrist actuators -->
  <transmission name="leftwristflexiontran">
    <type>transmission_interface/SimpleTransmission</type>
    <joint name="left_wrist_flexion_joint">
      <hardwareInterface>hardware_interface/EffortJointInterface</hardwareInterface>
    </joint>
    <actuator name="leftwristflexionmotor">
      <mechanicalReduction>50</mechanicalReduction>
    </actuator>
  </transmission>
  <!-- Shoulder and upper arm definitions-->
  <!-- "invisible" links that add DOF to the shoulder -->
  <link name="right_shoulder_roll_link">
    <visual>
      <origin rpy="0 0 0" xyz="0 0 0"/>
      <geometry>
        <sphere radius="0.01"/>
      </geometry>
    </visual>
    <inertial>
      <origin rpy="0 0 0" xyz="0 0 0"/>
      <mass value="0.01"/>
      <inertia ixx="4e-07" ixy="0.0" ixz="0.0" iyy="4e-07" iyz="0.0" izz="4e-07"/>
    </inertial>
  </link>
  <gazebo reference="right_shoulder_roll_link">
    <kp>10000.0</kp>
    <kd>10000.0</kd>
    <mu1>10.0</mu1>
    <mu2>10.0</mu2>
    <material>Gazebo/Red</material>
  </gazebo>
  <link name="right_shoulder_pitch_link">
    <visual>
      <origin rpy="0 0 0" xyz="0 0 0"/>
      <geometry>
        <sphere radius="0.01"/>
      </geometry>
    </visual>
    <inertial>
      <origin rpy="0 0 0" xyz="0 0 0"/>
      <mass value="0.01"/>
      <inertia ixx="4e-07" ixy="0.0" ixz="0.0" iyy="4e-07" iyz="0.0" izz="4e-07"/>
    </inertial>
  </link>
  <gazebo reference="right_shoulder_pitch_link">
    <kp>10000.0</kp>
    <kd>10000.0</kd>
    <mu1>10.0</mu1>
    <mu2>10.0</mu2>
    <material>Gazebo/Green</material>
  </gazebo>
  <link name="right_shoulder_yaw_link">
    <visual>
      <origin rpy="0 0 0" xyz="0 0 0"/>
      <geometry>
        <sphere radius="0.01"/>
      </geometry>
    </visual>
    <inertial>
      <origin rpy="0 0 0" xyz="0 0 0"/>
      <mass value="0.01"/>
      <inertia ixx="4e-07" ixy="0.0" ixz="0.0" iyy="4e-07" iyz="0.0" izz="4e-07"/>
    </inertial>
  </link>
  <gazebo reference="right_shoulder_yaw_link">
    <kp>10000.0</kp>
    <kd>10000.0</kd>
    <mu1>10.0</mu1>
    <mu2>10.0</mu2>
    <material>Gazebo/Blue</material>
  </gazebo>
  <link name="right_upper_arm_link">
    <visual>
      <origin rpy="0.0 0 0" xyz="0 0 0"/>
      <geometry>
        <!-- Material color set to white in blender -->
        <mesh filename="package://mannequin/models/mannequin/meshes/upper_arm_formatted.dae"/>
      </geometry>
    </visual>
    <collision>
      <origin rpy="0 0 0" xyz="0 0 -0.170"/>
      <geometry>
        <cylinder length="0.341" radius="0.042"/>
      </geometry>
    </collision>
    <inertial>
      <origin rpy="0 0 0" xyz="0 0 -0.170"/>
      <mass value="2.1"/>
      <inertia ixx="0.021275275" ixy="0.0" ixz="0.0" iyy="0.021275275" iyz="0.0" izz="0.0018522"/>
    </inertial>
  </link>
  <gazebo reference="right_upper_arm_link">
    <kp>5000.0</kp>
    <kd>5000.0</kd>
    <mu1>10.0</mu1>
    <mu2>10.0</mu2>
    <material>Gazebo/White</material>
  </gazebo>
  <joint name="right_shoulder_roll_joint" type="revolute">
    <hardwareInterface>hardware_interface/EffortJointInterface</hardwareInterface>
    <parent link="upper_body_link"/>
    <child link="right_shoulder_roll_link"/>
    <axis xyz="-1 0 0"/>
    <limit effort="200" lower="-1.05" upper="3.14" velocity="0.5"/>
    <origin rpy="0 0 0" xyz="0 -0.188 0.24"/>
  </joint>
  <joint name="right_shoulder_pitch_joint" type="revolute">
    <hardwareInterface>hardware_interface/EffortJointInterface</hardwareInterface>
    <parent link="right_shoulder_roll_link"/>
    <child link="right_shoulder_pitch_link"/>
    <axis xyz="0 1 0"/>
    <limit effort="200" lower="-1.3" upper="3.14" velocity="0.5"/>
    <origin rpy="0 0 0" xyz="0 0 0"/>
  </joint>
  <joint name="right_shoulder_yaw_joint" type="revolute">
    <hardwareInterface>hardware_interface/EffortJointInterface</hardwareInterface>
    <parent link="right_shoulder_pitch_link"/>
    <child link="right_shoulder_yaw_link"/>
    <axis xyz="0 0 1"/>
    <limit effort="200" lower="-1.0" upper="1.5" velocity="0.5"/>
    <origin rpy="0 0 0" xyz="0 0 0"/>
  </joint>
  <joint name="right_upper_arm_joint" type="fixed">
    <parent link="right_shoulder_yaw_link"/>
    <child link="right_upper_arm_link"/>
    <origin rpy="0 0 0" xyz="0 0 0"/>
  </joint>
  <!-- "Invisible" links for DOF of the elbow (flexion/extension[-0.17,2.62] and supination/pronation[-1.40,1.40]) -->
  <link name="right_elbow_flexion_link">
    <visual>
      <origin rpy="0 0 0" xyz="0 0 0"/>
      <geometry>
        <sphere radius="0.01"/>
      </geometry>
    </visual>
    <inertial>
      <origin rpy="0 0 0" xyz="0 0 0"/>
      <mass value="0.01"/>
      <inertia ixx="4e-07" ixy="0.0" ixz="0.0" iyy="4e-07" iyz="0.0" izz="4e-07"/>
    </inertial>
  </link>
  <gazebo reference="right_elbow_flexion_link">
    <kp>1000.0</kp>
    <kd>1000.0</kd>
    <mu1>10.0</mu1>
    <mu2>10.0</mu2>
    <material>Gazebo/Red</material>
  </gazebo>
  <link name="right_lower_arm_link">
    <visual>
      <origin rpy="0.0 0 0" xyz="0 0 0"/>
      <geometry>
        <!-- Material color set to white in blender -->
        <mesh filename="package://mannequin/models/mannequin/meshes/lower_arm_formatted.dae"/>
      </geometry>
    </visual>
    <collision>
      <origin rpy="0 0 0" xyz="0 0 -0.128"/>
      <geometry>
        <cylinder length="0.25" radius="0.035"/>
      </geometry>
    </collision>
    <inertial>
      <origin rpy="0 0 0" xyz="0 0 -0.128"/>
      <mass value="2.1"/>
      <inertia ixx="0.01038165" ixy="0.0" ixz="0.0" iyy="0.01038165" iyz="0.0" izz="0.0011025"/>
    </inertial>
  </link>
  <gazebo reference="right_lower_arm_link">
    <kp>5000.0</kp>
    <kd>5000.0</kd>
    <mu1>10.0</mu1>
    <mu2>10.0</mu2>
    <material>Gazebo/White</material>
  </gazebo>
  <joint name="right_elbow_flexion_joint" type="revolute">
    <hardwareInterface>hardware_interface/EffortJointInterface</hardwareInterface>
    <parent link="right_upper_arm_link"/>
    <child link="right_elbow_flexion_link"/>
    <axis xyz="0 -1 0"/>
    <limit effort="50" lower="-1.05" upper="3.14" velocity="0.5"/>
    <origin rpy="0 0.05 0" xyz="0 -0.01 -0.34"/>
  </joint>
  <joint name="right_lower_arm_joint" type="fixed">
    <parent link="right_elbow_flexion_link"/>
    <child link="right_lower_arm_link"/>
  </joint>
  <!-- Hand definitions -->
  <!-- Invisible links for flexion/extension and ulnar/radial deviation -->
  <link name="right_wrist_flexion_link">
    <visual>
      <origin rpy="0 0 0" xyz="0 0 0"/>
      <geometry>
        <sphere radius="0.01"/>
      </geometry>
    </visual>
    <inertial>
      <origin rpy="0 0 0" xyz="0 0 0"/>
      <mass value="0.01"/>
      <inertia ixx="4e-07" ixy="0.0" ixz="0.0" iyy="4e-07" iyz="0.0" izz="4e-07"/>
    </inertial>
  </link>
  <gazebo reference="right_wrist_flexion_link">
    <kp>1000.0</kp>
    <kd>1000.0</kd>
    <mu1>10.0</mu1>
    <mu2>10.0</mu2>
    <material>Gazebo/Red</material>
  </gazebo>
  <link name="right_hand_link">
    <visual>
      <origin rpy="0.0 -0.2 3.14" xyz="0 0 0"/>
      <geometry>
        <!-- Material color set to white in blender -->
        <mesh filename="package://mannequin/models/mannequin/meshes/hand_formatted.dae"/>
      </geometry>
    </visual>
    <collision>
      <origin rpy="0 0 0" xyz="0 0 -0.092"/>
      <geometry>
        <box size="0.077 0.028 0.184"/>
      </geometry>
    </collision>
    <inertial>
      <origin rpy="0 0 0" xyz="0 0 -0.092"/>
      <mass value="0.5"/>
      <inertia ixx="0.00144333333333" ixy="0.0" ixz="0.0" iyy="0.00165770833333" iyz="0.0" izz="0.000279708333333"/>
    </inertial>
  </link>
  <gazebo reference="right_hand_link">
    <kp>5000.0</kp>
    <kd>5000.0</kd>
    <mu1>10.0</mu1>
    <mu2>10.0</mu2>
    <material>Gazebo/White</material>
  </gazebo>
  <joint name="right_wrist_flexion_joint" type="revolute">
    <hardwareInterface>hardware_interface/EffortJointInterface</hardwareInterface>
    <parent link="right_lower_arm_link"/>
    <child link="right_wrist_flexion_link"/>
    <axis xyz="1 0 0"/>
    <limit effort="5" lower="-1.396" upper="1.22" velocity="0.5"/>
    <origin rpy="0 0 0" xyz="0 0 -0.25"/>
  </joint>
  <joint name="right_hand_joint" type="fixed">
    <parent link="right_wrist_flexion_link"/>
    <child link="right_hand_link"/>
    <origin rpy="0 0 -1.57" xyz="0 0 0"/>
  </joint>
  <!-- ***** Actuator Definitions for arm ***** -->
  <!-- Shoulder actuators -->
  <transmission name="rightshoulderrolltran">
    <type>transmission_interface/SimpleTransmission</type>
    <joint name="right_shoulder_roll_joint">
      <hardwareInterface>hardware_interface/EffortJointInterface</hardwareInterface>
    </joint>
    <actuator name="rightshoulderrollmotor">
      <mechanicalReduction>50</mechanicalReduction>
    </actuator>
  </transmission>
  <transmission name="rightshoulderpitchtran">
    <type>transmission_interface/SimpleTransmission</type>
    <joint name="right_shoulder_pitch_joint">
      <hardwareInterface>hardware_interface/EffortJointInterface</hardwareInterface>
    </joint>
    <actuator name="rightshoulderpitchmotor">
      <mechanicalReduction>50</mechanicalReduction>
    </actuator>
  </transmission>
  <transmission name="rightshoulderyawtran">
    <type>transmission_interface/SimpleTransmission</type>
    <joint name="right_shoulder_yaw_joint">
      <hardwareInterface>hardware_interface/EffortJointInterface</hardwareInterface>
    </joint>
    <actuator name="rightshoulderyawmotor">
      <mechanicalReduction>50</mechanicalReduction>
    </actuator>
  </transmission>
  <!-- Elbow actuators -->
  <transmission name="rightelbowflexiontran">
    <type>transmission_interface/SimpleTransmission</type>
    <joint name="right_elbow_flexion_joint">
      <hardwareInterface>hardware_interface/EffortJointInterface</hardwareInterface>
    </joint>
    <actuator name="rightelbowflexionmotor">
      <mechanicalReduction>50</mechanicalReduction>
    </actuator>
  </transmission>
  <!-- Wrist actuators -->
  <transmission name="rightwristflexiontran">
    <type>transmission_interface/SimpleTransmission</type>
    <joint name="right_wrist_flexion_joint">
      <hardwareInterface>hardware_interface/EffortJointInterface</hardwareInterface>
    </joint>
    <actuator name="rightwristflexionmotor">
      <mechanicalReduction>50</mechanicalReduction>
    </actuator>
  </transmission>
  <link name="right_thigh_link">
    <visual>
      <origin rpy="0.0 0 0" xyz="0 0 0"/>
      <geometry>
        <!-- Material color set to white in blender -->
        <mesh filename="package://mannequin/models/mannequin/meshes/upper_leg_formatted.dae"/>
      </geometry>
    </visual>
    <collision>
      <origin rpy="0 0 0" xyz="0 0 -0.240"/>
      <geometry>
        <cylinder length=".475" radius="0.095"/>
      </geometry>
    </collision>
    <inertial>
      <origin rpy="0 0 0" xyz="0 0 -0.240"/>
      <mass value="7.4"/>
      <inertia ixx="0.15877625" ixy="0.0" ixz="0.0" iyy="0.15877625" iyz="0.0" izz="0.0333925"/>
    </inertial>
  </link>
  <gazebo reference="right_thigh_link">
    <kp>5000.0</kp>
    <kd>5000.0</kd>
    <mu1>10.0</mu1>
    <mu2>10.0</mu2>
    <material>Gazebo/White</material>
  </gazebo>
  <link name="right_calf_link">
    <visual>
      <origin rpy="0.0 0 0" xyz="0 0 0"/>
      <geometry>
        <!-- Material color set to white in blender -->
        <mesh filename="package://mannequin/models/mannequin/meshes/lower_leg_formatted.dae"/>
      </geometry>
    </visual>
    <collision>
      <origin rpy="0 0 0" xyz="0 0 -0.217"/>
      <geometry>
        <cylinder length=".433" radius="0.056"/>
      </geometry>
    </collision>
    <inertial>
      <origin rpy="0 0 0" xyz="0 0 -0.217"/>
      <mass value="2.9"/>
      <inertia ixx="0.0475834416667" ixy="0.0" ixz="0.0" iyy="0.0475834416667" iyz="0.0" izz="0.0045472"/>
    </inertial>
  </link>
  <gazebo reference="right_calf_link">
    <kp>5000.0</kp>
    <kd>5000.0</kd>
    <mu1>10.0</mu1>
    <mu2>10.0</mu2>
    <material>Gazebo/White</material>
  </gazebo>
  <link name="right_foot_link">
    <visual>
      <origin rpy="0.0 0 0" xyz="0 0 0"/>
      <geometry>
        <!-- Material color set to white in blender -->
        <mesh filename="package://mannequin/models/mannequin/meshes/foot_formatted.dae"/>
      </geometry>
    </visual>
    <collision>
      <origin rpy="0 0 0" xyz="0.1205 0.0445 -0.014"/>
      <geometry>
        <!--w=0.089 d=.028 h=0.241-->
        <box size="0.241 0.089 0.028"/>
      </geometry>
    </collision>
    <inertial>
      <origin rpy="0 0 0" xyz="0.1205 0.0445 -0.014"/>
      <mass value="1.2"/>
      <!--Iw = 0.0058865, Id = 0.0066002, Ih = 0.0008705-->
      <inertia ixx="0.0008705" ixy="0.0" ixz="0.0" iyy="0.0058865" iyz="0.0" izz="0.0066002"/>
    </inertial>
  </link>
  <gazebo reference="right_foot_link">
    <kp>5000.0</kp>
    <kd>5000.0</kd>
    <mu1>10.0</mu1>
    <mu2>10.0</mu2>
    <material>Gazebo/White</material>
  </gazebo>
  <joint name="right_thigh_joint" type="revolute">
    <hardwareInterface>hardware_interface/EffortJointInterface</hardwareInterface>
    <parent link="lower_body_link"/>
    <child link="right_thigh_link"/>
    <axis xyz="0 1 0"/>
    <!-- Kodak's does not have data on thigh ROM, I estimated here -->
    <limit effort="2000" lower="-1.3" upper="1.57" velocity="2.0"/>
    <origin rpy="0 -0.1 0" xyz="-0.015 0.097 0.025"/>
  </joint>
  <joint name="right_knee_joint" type="revolute">
    <hardwareInterface>hardware_interface/EffortJointInterface</hardwareInterface>
    <parent link="right_thigh_link"/>
    <child link="right_calf_link"/>
    <axis xyz="0 1 0"/>
    <limit effort="2000" lower="-0.17" upper="2.36" velocity="2.0"/>
    <origin rpy="0 -0.1 0" xyz="0 0 -0.433"/>
  </joint>
  <joint name="right_ankle_joint" type="revolute">
    <hardwareInterface>hardware_interface/EffortJointInterface</hardwareInterface>
    <parent link="right_calf_link"/>
    <child link="right_foot_link"/>
    <axis xyz="0 1 0"/>
    <!-- Kodak's does not have data on thigh ROM, I estimated here -->
    <limit effort="2000" lower="-0.35" upper="0.87" velocity="2.0"/>
    <origin rpy="0 -1.0 0" xyz="0 0 -0.433"/>
  </joint>
  <transmission name="righthiprolltran">
    <type>transmission_interface/SimpleTransmission</type>
    <joint name="right_thigh_joint">
      <hardwareInterface>hardware_interface/EffortJointInterface</hardwareInterface>
    </joint>
    <actuator name="righthiprollmotor">
      <mechanicalReduction>50</mechanicalReduction>
    </actuator>
  </transmission>
  <transmission name="rightkneerolltran">
    <type>transmission_interface/SimpleTransmission</type>
    <joint name="right_knee_joint">
      <hardwareInterface>hardware_interface/EffortJointInterface</hardwareInterface>
    </joint>
    <actuator name="rightkneerollmotor">
      <mechanicalReduction>50</mechanicalReduction>
    </actuator>
  </transmission>
  <transmission name="rightanklerolltran">
    <type>transmission_interface/SimpleTransmission</type>
    <joint name="right_ankle_joint">
      <hardwareInterface>hardware_interface/EffortJointInterface</hardwareInterface>
    </joint>
    <actuator name="rightanklerollmotor">
      <mechanicalReduction>50</mechanicalReduction>
    </actuator>
  </transmission>
  <link name="left_thigh_link">
    <visual>
      <origin rpy="0.0 0 0" xyz="0 0 0"/>
      <geometry>
        <!-- Material color set to white in blender -->
        <mesh filename="package://mannequin/models/mannequin/meshes/upper_leg_formatted.dae"/>
      </geometry>
    </visual>
    <collision>
      <origin rpy="0 0 0" xyz="0 0 -0.240"/>
      <geometry>
        <cylinder length=".475" radius="0.095"/>
      </geometry>
    </collision>
    <inertial>
      <origin rpy="0 0 0" xyz="0 0 -0.240"/>
      <mass value="7.4"/>
      <inertia ixx="0.15877625" ixy="0.0" ixz="0.0" iyy="0.15877625" iyz="0.0" izz="0.0333925"/>
    </inertial>
  </link>
  <gazebo reference="left_thigh_link">
    <kp>5000.0</kp>
    <kd>5000.0</kd>
    <mu1>10.0</mu1>
    <mu2>10.0</mu2>
    <material>Gazebo/White</material>
  </gazebo>
  <link name="left_calf_link">
    <visual>
      <origin rpy="0.0 0 0" xyz="0 0 0"/>
      <geometry>
        <!-- Material color set to white in blender -->
        <mesh filename="package://mannequin/models/mannequin/meshes/lower_leg_formatted.dae"/>
      </geometry>
    </visual>
    <collision>
      <origin rpy="0 0 0" xyz="0 0 -0.217"/>
      <geometry>
        <cylinder length=".433" radius="0.056"/>
      </geometry>
    </collision>
    <inertial>
      <origin rpy="0 0 0" xyz="0 0 -0.217"/>
      <mass value="2.9"/>
      <inertia ixx="0.0475834416667" ixy="0.0" ixz="0.0" iyy="0.0475834416667" iyz="0.0" izz="0.0045472"/>
    </inertial>
  </link>
  <gazebo reference="left_calf_link">
    <kp>5000.0</kp>
    <kd>5000.0</kd>
    <mu1>10.0</mu1>
    <mu2>10.0</mu2>
    <material>Gazebo/White</material>
  </gazebo>
  <link name="left_foot_link">
    <visual>
      <origin rpy="0.0 0 0" xyz="0 0 0"/>
      <geometry>
        <!-- Material color set to white in blender -->
        <mesh filename="package://mannequin/models/mannequin/meshes/foot_formatted.dae"/>
      </geometry>
    </visual>
    <collision>
      <origin rpy="0 0 0" xyz="0.1205 0.0445 -0.014"/>
      <geometry>
        <!--w=0.089 d=.028 h=0.241-->
        <box size="0.241 0.089 0.028"/>
      </geometry>
    </collision>
    <inertial>
      <origin rpy="0 0 0" xyz="0.1205 0.0445 -0.014"/>
      <mass value="1.2"/>
      <!--Iw = 0.0058865, Id = 0.0066002, Ih = 0.0008705-->
      <inertia ixx="0.0008705" ixy="0.0" ixz="0.0" iyy="0.0058865" iyz="0.0" izz="0.0066002"/>
    </inertial>
  </link>
  <gazebo reference="left_foot_link">
    <kp>5000.0</kp>
    <kd>5000.0</kd>
    <mu1>10.0</mu1>
    <mu2>10.0</mu2>
    <material>Gazebo/White</material>
  </gazebo>
  <joint name="left_thigh_joint" type="revolute">
    <hardwareInterface>hardware_interface/EffortJointInterface</hardwareInterface>
    <parent link="lower_body_link"/>
    <child link="left_thigh_link"/>
    <axis xyz="0 1 0"/>
    <!-- Kodak's does not have data on thigh ROM, I estimated here -->
    <limit effort="2000" lower="-1.3" upper="1.57" velocity="2.0"/>
    <origin rpy="0 -0.1 0" xyz="-0.015 -0.097 0.025"/>
  </joint>
  <joint name="left_knee_joint" type="revolute">
    <hardwareInterface>hardware_interface/EffortJointInterface</hardwareInterface>
    <parent link="left_thigh_link"/>
    <child link="left_calf_link"/>
    <axis xyz="0 1 0"/>
    <limit effort="2000" lower="-0.17" upper="2.36" velocity="2.0"/>
    <origin rpy="0 -0.1 0" xyz="0 0 -0.433"/>
  </joint>
  <joint name="left_ankle_joint" type="revolute">
    <hardwareInterface>hardware_interface/EffortJointInterface</hardwareInterface>
    <parent link="left_calf_link"/>
    <child link="left_foot_link"/>
    <axis xyz="0 1 0"/>
    <!-- Kodak's does not have data on thigh ROM, I estimated here -->
    <limit effort="2000" lower="-0.35" upper="0.87" velocity="2.0"/>
    <origin rpy="0 -1.0 0" xyz="0 0 -0.433"/>
  </joint>
  <transmission name="lefthiprolltran">
    <type>transmission_interface/SimpleTransmission</type>
    <joint name="left_thigh_joint">
      <hardwareInterface>hardware_interface/EffortJointInterface</hardwareInterface>
    </joint>
    <actuator name="lefthiprollmotor">
      <mechanicalReduction>50</mechanicalReduction>
    </actuator>
  </transmission>
  <transmission name="leftkneerolltran">
    <type>transmission_interface/SimpleTransmission</type>
    <joint name="left_knee_joint">
      <hardwareInterface>hardware_interface/EffortJointInterface</hardwareInterface>
    </joint>
    <actuator name="leftkneerollmotor">
      <mechanicalReduction>50</mechanicalReduction>
    </actuator>
  </transmission>
  <transmission name="leftanklerolltran">
    <type>transmission_interface/SimpleTransmission</type>
    <joint name="left_ankle_joint">
      <hardwareInterface>hardware_interface/EffortJointInterface</hardwareInterface>
    </joint>
    <actuator name="leftanklerollmotor">
      <mechanicalReduction>50</mechanicalReduction>
    </actuator>
  </transmission>
</robot>
